#VRML_SIM R2020a utf8
WorldInfo {
}
Viewpoint {
  orientation -0.9917158627855804 0.06517299495672754 -0.11068933204163035 0.9496612833337446
  position 0.12647822427883565 0.6551619328542587 0.4186420287984249
}
TexturedBackground {
}
TexturedBackgroundLight {
}
RectangleArena {
}
Robot {
  translation 0 0.14 0
  children [
    DEF NAV_WHEELS Group {
      children [
        DEF WHEEL_1 HingeJoint {
          jointParameters HingeJointParameters {
            anchor 0.04999999999999991 1.81802e-07 0.04000000266020092
          }
          device [
            RotationalMotor {
              name "wheel1"
            }
          ]
          endPoint Solid {
            translation 0.04999999999999991 1.81802e-07 0.04000000266020092
            rotation -6.255693872693552e-08 -3.947854551184206e-09 0.999999999999998 1.5707999999999998
            children [
              Shape {
                appearance DEF NAV_WHEEL_VIS PBRAppearance {
                }
                geometry DEF NAV_WHEEL_GEO Cylinder {
                  height 0.01
                  radius 0.02
                }
              }
            ]
            name "wheel1"
            boundingObject USE NAV_WHEEL_GEO
            physics Physics {
            }
          }
        }
        DEF WHEEL_2 HingeJoint {
          jointParameters HingeJointParameters {
            anchor -0.05 -1.85518e-07 0.04
          }
          device [
            RotationalMotor {
              name "wheel2"
            }
          ]
          endPoint Solid {
            translation -0.05 -1.85518e-07 0.04
            rotation -6.255693872693552e-08 -3.947854551184206e-09 0.999999999999998 1.5707999999999998
            children [
              Shape {
                appearance DEF NAV_WHEEL_VIS PBRAppearance {
                }
                geometry DEF NAV_WHEEL_GEO Cylinder {
                  height 0.01
                  radius 0.02
                }
              }
            ]
            name "wheel1(1)"
            boundingObject USE NAV_WHEEL_GEO
            physics Physics {
            }
          }
        }
        DEF WHEEL_3 HingeJoint {
          jointParameters HingeJointParameters {
            anchor -0.05 -1.90792e-07 -0.05
          }
          device [
            RotationalMotor {
              name "wheel3"
            }
          ]
          endPoint Solid {
            translation -0.05 -1.90792e-07 -0.05
            rotation -6.255693872693552e-08 -3.947854551184206e-09 0.999999999999998 1.5707999999999998
            children [
              Shape {
                appearance DEF NAV_WHEEL_VIS PBRAppearance {
                }
                geometry DEF NAV_WHEEL_GEO Cylinder {
                  height 0.01
                  radius 0.02
                }
              }
            ]
            name "wheel1(2)"
            boundingObject USE NAV_WHEEL_GEO
            physics Physics {
            }
          }
        }
        DEF WHEEL_4 HingeJoint {
          jointParameters HingeJointParameters {
            anchor 0.05 1.76528e-07 -0.05
          }
          device [
            RotationalMotor {
              name "wheel4"
            }
          ]
          endPoint Solid {
            translation 0.05 1.76528e-07 -0.05
            rotation -6.255693872693552e-08 -3.947854551184206e-09 0.999999999999998 1.5707999999999998
            children [
              Shape {
                appearance DEF NAV_WHEEL_VIS PBRAppearance {
                }
                geometry DEF NAV_WHEEL_GEO Cylinder {
                  height 0.01
                  radius 0.02
                }
              }
            ]
            name "wheel1(3)"
            boundingObject USE NAV_WHEEL_GEO
            physics Physics {
            }
          }
        }
      ]
    }
    DEF NAV_BASE Solid {
      children [
        Shape {
          appearance PBRAppearance {
            baseColor 0 0 0
            metalness 0
          }
          geometry DEF NAV_BASE_GEO Box {
            size 0.1 0.01 0.1
          }
        }
      ]
    }
  ]
  name "navbot_kiosk"
  model "model-v1"
  boundingObject USE NAV_BASE_GEO
  physics Physics {
  }
  controller "ros"
}
